[NbConvertApp] Converting notebook ml_neptuneAI.ipynb to notebook
Traceback (most recent call last):
  File "/home2/qlpd78/anaconda3/bin/jupyter-nbconvert", line 11, in <module>
    sys.exit(main())
  File "/home2/qlpd78/anaconda3/lib/python3.9/site-packages/jupyter_core/application.py", line 264, in launch_instance
    return super(JupyterApp, cls).launch_instance(argv=argv, **kwargs)
  File "/home2/qlpd78/anaconda3/lib/python3.9/site-packages/traitlets/config/application.py", line 846, in launch_instance
    app.start()
  File "/home2/qlpd78/anaconda3/lib/python3.9/site-packages/nbconvert/nbconvertapp.py", line 369, in start
    self.convert_notebooks()
  File "/home2/qlpd78/anaconda3/lib/python3.9/site-packages/nbconvert/nbconvertapp.py", line 541, in convert_notebooks
    self.convert_single_notebook(notebook_filename)
  File "/home2/qlpd78/anaconda3/lib/python3.9/site-packages/nbconvert/nbconvertapp.py", line 506, in convert_single_notebook
    output, resources = self.export_single_notebook(notebook_filename, resources, input_buffer=input_buffer)
  File "/home2/qlpd78/anaconda3/lib/python3.9/site-packages/nbconvert/nbconvertapp.py", line 435, in export_single_notebook
    output, resources = self.exporter.from_filename(notebook_filename, resources=resources)
  File "/home2/qlpd78/anaconda3/lib/python3.9/site-packages/nbconvert/exporters/exporter.py", line 190, in from_filename
    return self.from_file(f, resources=resources, **kw)
  File "/home2/qlpd78/anaconda3/lib/python3.9/site-packages/nbconvert/exporters/exporter.py", line 208, in from_file
    return self.from_notebook_node(nbformat.read(file_stream, as_version=4), resources=resources, **kw)
  File "/home2/qlpd78/anaconda3/lib/python3.9/site-packages/nbconvert/exporters/notebook.py", line 32, in from_notebook_node
    nb_copy, resources = super().from_notebook_node(nb, resources, **kw)
  File "/home2/qlpd78/anaconda3/lib/python3.9/site-packages/nbconvert/exporters/exporter.py", line 147, in from_notebook_node
    nb_copy, resources = self._preprocess(nb_copy, resources)
  File "/home2/qlpd78/anaconda3/lib/python3.9/site-packages/nbconvert/exporters/exporter.py", line 334, in _preprocess
    nbc, resc = preprocessor(nbc, resc)
  File "/home2/qlpd78/anaconda3/lib/python3.9/site-packages/nbconvert/preprocessors/base.py", line 47, in __call__
    return self.preprocess(nb, resources)
  File "/home2/qlpd78/anaconda3/lib/python3.9/site-packages/nbconvert/preprocessors/execute.py", line 84, in preprocess
    self.preprocess_cell(cell, resources, index)
  File "/home2/qlpd78/anaconda3/lib/python3.9/site-packages/nbconvert/preprocessors/execute.py", line 105, in preprocess_cell
    cell = self.execute_cell(cell, index, store_history=True)
  File "/home2/qlpd78/anaconda3/lib/python3.9/site-packages/nbclient/util.py", line 84, in wrapped
    return just_run(coro(*args, **kwargs))
  File "/home2/qlpd78/anaconda3/lib/python3.9/site-packages/nbclient/util.py", line 62, in just_run
    return loop.run_until_complete(coro)
  File "/home2/qlpd78/anaconda3/lib/python3.9/asyncio/base_events.py", line 647, in run_until_complete
    return future.result()
  File "/home2/qlpd78/anaconda3/lib/python3.9/site-packages/nbclient/client.py", line 965, in async_execute_cell
    await self._check_raise_for_error(cell, cell_index, exec_reply)
  File "/home2/qlpd78/anaconda3/lib/python3.9/site-packages/nbclient/client.py", line 862, in _check_raise_for_error
    raise CellExecutionError.from_cell_and_msg(cell, exec_reply_content)
nbclient.exceptions.CellExecutionError: An error occurred while executing the following cell:
------------------
total = []
inc=[]
for i in range(10):
    val,wrong=inference(myModel, val_dl)
    total.append(val)
    inc.append(wrong)
    run["evaluation/accuracy"] = val
run.stop()
   
    
------------------

[0;31m---------------------------------------------------------------------------[0m
[0;31mInactiveRunException[0m                      Traceback (most recent call last)
Input [0;32mIn [8][0m, in [0;36m<cell line: 3>[0;34m()[0m
[1;32m      5[0m     total[38;5;241m.[39mappend(val)
[1;32m      6[0m     inc[38;5;241m.[39mappend(wrong)
[0;32m----> 7[0m     run[[38;5;124m"[39m[38;5;124mevaluation/accuracy[39m[38;5;124m"[39m] [38;5;241m=[39m val
[1;32m      8[0m run[38;5;241m.[39mstop()

File [0;32m~/anaconda3/lib/python3.9/site-packages/neptune/new/metadata_containers/metadata_container.py:88[0m, in [0;36mensure_not_stopped.<locals>.inner_fun[0;34m(self, *args, **kwargs)[0m
[1;32m     86[0m [38;5;28;01mif[39;00m [38;5;28mself[39m[38;5;241m.[39m_state [38;5;241m==[39m ContainerState[38;5;241m.[39mSTOPPED:
[1;32m     87[0m     [38;5;28;01mif[39;00m [38;5;28mself[39m[38;5;241m.[39mcontainer_type [38;5;241m==[39m ContainerType[38;5;241m.[39mRUN:
[0;32m---> 88[0m         [38;5;28;01mraise[39;00m InactiveRunException(label[38;5;241m=[39m[38;5;28mself[39m[38;5;241m.[39m_label)
[1;32m     89[0m     [38;5;28;01melif[39;00m [38;5;28mself[39m[38;5;241m.[39mcontainer_type [38;5;241m==[39m ContainerType[38;5;241m.[39mPROJECT:
[1;32m     90[0m         [38;5;28;01mraise[39;00m InactiveProjectException(label[38;5;241m=[39m[38;5;28mself[39m[38;5;241m.[39m_label)

[0;31mInactiveRunException[0m: 
[95m
----InactiveRunException----------------------------------------
[0m
It seems you are trying to log (or fetch) metadata to a run that was stopped (CRAS-1).

What should I do?
    - Resume the run to continue logging to it:
    https://docs.neptune.ai/how-to-guides/neptune-api/resume-run#how-to-resume-run
    - Don't invoke `stop()` on a run that you want to access. If you want to stop monitoring only,
    you can resume a run in read-only mode:
    https://docs.neptune.ai/you-should-know/connection-modes#read-only

You may also want to check the following docs pages:
    - https://docs.neptune.ai/api-reference/run#.stop
    - https://docs.neptune.ai/you-should-know/connection-modes

[92mNeed help?[0m-> https://docs.neptune.ai/getting-started/getting-help

InactiveRunException: 
[95m
----InactiveRunException----------------------------------------
[0m
It seems you are trying to log (or fetch) metadata to a run that was stopped (CRAS-1).

What should I do?
    - Resume the run to continue logging to it:
    https://docs.neptune.ai/how-to-guides/neptune-api/resume-run#how-to-resume-run
    - Don't invoke `stop()` on a run that you want to access. If you want to stop monitoring only,
    you can resume a run in read-only mode:
    https://docs.neptune.ai/you-should-know/connection-modes#read-only

You may also want to check the following docs pages:
    - https://docs.neptune.ai/api-reference/run#.stop
    - https://docs.neptune.ai/you-should-know/connection-modes

[92mNeed help?[0m-> https://docs.neptune.ai/getting-started/getting-help


srun: error: gpu5: task 0: Exited with exit code 1
